<mujoco model="gensong_robot_urdf">
  <compiler angle="radian" meshdir="./meshes/" />

  <!-- <default>
    <geom material="silver_mat" type="mesh"/>
    <joint damping="0.1" armature="0.01" frictionloss="0.1"/>
    <default class="visual">
        <geom group="2" type="mesh" density="0" material="silver_mat" contype="0" conaffinity="0"/>
    </default>
    <default class="collision">
        <geom group="3" rgba="0.7 0.7 0.7 0.5" type="capsule" contype="1" conaffinity="1"/>
        <default class="foot_capsule">
            <geom type="capsule" size="0.01"/>
        </default>
    </default>
    <site group="5" rgba="1 0 0 1"/>
    <default class="arm1_2">
      <joint armature="0.5" damping="6" frictionloss="3"/>
    </default>
    <default class="arm3_4">
      <joint armature="0.4" damping="5" frictionloss="2.5"/>
    </default>
    <default class="arm5">
      <joint armature="0.2" damping="4" frictionloss="2"/>
    </default>
    <default class="leg3">
      <joint armature="2" damping="8" frictionloss="8"/>
    </default>
    <default class="leg4">
      <joint armature="2.5" damping="10" frictionloss="10"/>
    </default>
    <default class="leg5">
      <joint armature="0.2" damping="4" frictionloss="2"/>
    </default>
    <default class="wheel">
      <joint armature="0.01" damping="2.0" frictionloss="0.02"/>
    </default>
    <default class="middle">
      <joint armature="1.5" damping="8.0" frictionloss="5.0"/>
    </default>
  </default> -->
  <default>
    <geom material="silver_mat" type="mesh"/>
    <joint damping="0.1" armature="0.01" frictionloss="0.1"/>
    <default class="visual">
        <geom group="2" type="mesh" density="0" material="silver_mat" contype="0" conaffinity="0"/>
    </default>
    <default class="collision">
        <geom group="3" rgba="0.7 0.7 0.7 0.5" type="capsule" contype="1" conaffinity="1"/>
        <default class="foot_capsule">
            <geom type="capsule" size="0.01"/>
        </default>
    </default>
    <site group="5" rgba="1 0 0 1"/>
    <default class="arm1_2">
      <joint armature="2.26901" damping="20.741" frictionloss="16"/>
    </default>
    <default class="arm3_4">
      <joint armature="0.6021" damping="3.4423" frictionloss="4.461"/>
    </default>
    <default class="arm5">
      <joint armature="0.134112" damping="1.59352" frictionloss="2.002"/>
    </default>
    <default class="leg3">
      <joint armature="15.5611502228" damping="168.7711104376" frictionloss="33.9204772059"/>
    </default>
    <default class="leg4">
      <joint armature="10.9041046071" damping="106.2846631079" frictionloss="32.0843674861"/>
    </default>
    <default class="leg5">
      <joint armature="0.134112" damping="1.59352" frictionloss="2.002"/>
    </default>
    <default class="wheel">
      <joint armature="0.0067368543" damping="0.001" frictionloss="0.2876406446"/>
    </default>
    <default class="middle">
      <joint armature="2.0385298285" damping="20.5560147798" frictionloss="8.3756844594"/>
    </default>
  </default>
  <asset>
    <material name="silver_mat" rgba="0.75294 0.75294 0.75294 1"/>
    
    <mesh name="body" file="body.STL"/>
    <mesh name="head" file="head.STL"/>
    <mesh name="waist1" file="waist1.STL"/>
    <mesh name="waist2" file="waist2.STL"/>
    
    <mesh name="left_arm_1" file="left_arm_1.STL"/>
    <mesh name="left_arm_2" file="left_arm_2.STL"/>
    <mesh name="left_arm_3" file="left_arm_3.STL"/>
    <mesh name="left_arm_4" file="left_arm_4.STL"/>
    <mesh name="left_arm_5" file="left_arm_5.STL"/>

    <mesh name="right_arm_1" file="right_arm_1.STL"/>
    <mesh name="right_arm_2" file="right_arm_2.STL"/>
    <mesh name="right_arm_3" file="right_arm_3.STL"/>
    <mesh name="right_arm_4" file="right_arm_4.STL"/>
    <mesh name="right_arm_5" file="right_arm_5.STL"/>

    <mesh name="left_leg_1" file="left_leg_1.STL"/>
    <mesh name="left_leg_2" file="left_leg_2.STL"/>
    <mesh name="left_leg_3" file="left_leg_3.STL"/>
    <mesh name="left_leg_4" file="left_leg_4.STL"/>
    <mesh name="left_leg_5" file="left_leg_5.STL"/>
    <mesh name="left_wheel_1" file="left_wheel_1.STL"/>
    <mesh name="left_wheel_2" file="left_wheel_2.STL"/>

    <mesh name="right_leg_1" file="right_leg_1.STL"/>
    <mesh name="right_leg_2" file="right_leg_2.STL"/>
    <mesh name="right_leg_3" file="right_leg_3.STL"/>
    <mesh name="right_leg_4" file="right_leg_4.STL"/>
    <mesh name="right_leg_5" file="right_leg_5.STL"/>
    <mesh name="right_wheel_1" file="right_wheel_1.STL"/>
    <mesh name="right_wheel_2" file="right_wheel_2.STL"/>
  </asset>
  <worldbody>
    <!-- <body name="head_mocap" mocap="true" pos="0 0 2.1035">
      <geom type="sphere" size="0.05" rgba="1 0 0 0.5" contype="0" conaffinity="0"/>
    </body> -->
    <body name="body" pos="0 0 1.40">
      <site name="imu" size="0.01" pos="0 0 0" rgba="1 0 0 1" />
      <inertial pos="0.00888 -0.00078 -0.1632" mass="15.52189" fullinertia="0.2489 0.2062 0.14336 0.00132 0.00782 0.00085"/>
      <geom mesh="body" class="visual"/>
      <geom name="body_collision" class="collision" type="box" size="0.15 0.175 0.225" pos="0 0 -0.1" /> 
      <!-- <joint name="floating_base_joint" type="free"/> -->
      <joint name="floating_base_joint" type="free" limited="false" actuatorfrclimited="false" />
      <body name="head" pos="0 0 0.1035">
        <inertial pos="0.03712 -0.00640 0.14984" mass="3.09885" fullinertia="0.01485 0.01088 0.01952 0.00228 -0.00118 0.00065"/>
        <joint name="joint_head" axis="0 0 1" range="-1.57079632679489 1.57079632679489"/>
        <geom mesh="head" class="visual"/>
        <geom name="head_collision" class="collision" type="cylinder" size="0.135 0.1225" pos="0.04 0 0.15"  />
      </body>

      <body name="left_arm_1" pos="0 0.1523 0">
        <inertial pos="0.00329 -0.02828 0.00012" mass="2.10662" fullinertia="0.00478 0.00277 0.00497 -0.00057 0.00002 0.00002"/>
        <joint name="joint_left_arm_1" axis="0 -1 0" range="-3.14159265358979 3.14159265358979" class="arm1_2"/>
        <geom mesh="left_arm_1" class="visual"/>
        
        <body name="left_arm_2" pos="0 0.088 -0.012">
          <inertial pos="0.00778 0.01809 -0.03134" mass="2.82187" fullinertia="0.01065 0.00851 0.00445 0.00037 -0.00064 0.00352"/>
          <joint name="joint_left_arm_2" axis="1 0 0" range="-0.740368668695995 2.284112392084979" class="arm1_2"/>
          <geom mesh="left_arm_2" class="visual"/>
          <geom name="left_arm_2_collision" class="collision" type="cylinder" size="0.04 0.0675" pos="0 0.04 -0.07" euler="0.5236 0 0"  />

          <body name="left_arm_3" pos="0 0.06925 -0.11994" euler="0.5236 0 0">
            <inertial pos="-0.00092 -0.01121 -0.14409" mass="1.19499" fullinertia="0.00292 0.00291 0.00076 0.00000 0.00006 -0.00011"/>
            <joint name="joint_left_arm_3" axis="0 0 -1" range="-3.14159265358979 3.14159265358979" class="arm3_4"/>
            <geom mesh="left_arm_3" class="visual"/>
            <geom name="left_arm_3_collision" class="collision" type="cylinder" size="0.038 0.0375" pos="0 0 -0.055"  />

            <body name="left_arm_4" pos="0 0 -0.1615">
              <inertial pos="-0.00811 -0.00576 -0.07659" mass="0.76936" fullinertia="0.00182 0.00169 0.00060 0.00003 -0.00010 0.00028"/>
              <joint name="joint_left_arm_4" axis="0 -1 0" range="-0.700924227600923 2.47766940613115" class="arm3_4"/>
              <geom mesh="left_arm_4" class="visual"/>
              <geom name="left_arm_4_1_collision" class="collision" type="sphere" size="0.033" pos="-0.01 0 0"  />
              <geom name="left_arm_4_2_collision" class="collision" type="cylinder" size="0.033 0.0535" pos="-0.01 0 -0.0565"  />

              <body name="left_arm_5" pos="-0.01 0 -0.122">
                <inertial pos="0.00000 -0.01527 -0.13525" mass="0.43731" fullinertia="0.00222 0.00208 0.00044 0 0 -0.00029"/>
                <joint name="joint_left_arm_5" axis="0 0 1" range="-3.14159265358979 3.14159265358979" class="arm5"/>
                <geom mesh="left_arm_5" class="visual"/>
                <geom name="left_arm_5_1_collision" class="collision" type="box" size="0.03 0.005 0.07" pos="0 -0.04 -0.185"  />
                <geom name="left_arm_5_2_collision" class="collision" type="cylinder" size="0.033 0.104" pos="0 0 -0.104"  />
              </body>
            </body>
          </body>
        </body>
      </body>

      <body name="right_arm_1" pos="0 -0.1523 0">
        <inertial pos="-0.00329 0.02828 0.00012" mass="2.10662" fullinertia="0.00478 0.00277 0.00497 -0.00057 -0.00002 -0.00002"/>
        <joint name="joint_right_arm_1" axis="0 1 0" range="-3.14159265358979 3.14159265358979" class="arm1_2"/>
        <geom mesh="right_arm_1" class="visual"/>

        <body name="right_arm_2" pos="0 -0.088 -0.012">
          <inertial pos="-0.00778 -0.01809 -0.03134" mass="2.82187" fullinertia="0.01065 0.00851 0.00445 0.00037 0.00064 -0.00352"/>
          <joint name="joint_right_arm_2" axis="1 0 0" range="-2.284112392084979 0.740368668695995" class="arm1_2"/>
          <geom mesh="right_arm_2" class="visual"/>
          <geom name="right_arm_2_collision" class="collision" type="cylinder" size="0.04 0.0675" pos="0 -0.04 -0.07" euler="-0.5236 0 0"  />

          <body name="right_arm_3" pos="0 -0.06925 -0.11994" euler="-0.5236 0 0">
            <inertial pos="-0.00092 -0.01121 -0.14409" mass="1.19499" fullinertia="0.00292 0.00291 0.00076 0.00000 0.00006 -0.00011"/>
            <joint name="joint_right_arm_3" axis="0 0 -1" range="-3.14159265358979 3.14159265358979" class="arm3_4"/>
            <geom mesh="right_arm_3" class="visual"/>
            <geom name="right_arm_3_collision" class="collision" type="cylinder" size="0.038 0.0375" pos="0 0 -0.055"  />

            <body name="right_arm_4" pos="0 0 -0.1615">
              <inertial pos="-0.00811 -0.00576 -0.07659" mass="0.76936" fullinertia="0.00182 0.00169 0.00060 0.00003 -0.00010 0.00028"/>
              <joint name="joint_right_arm_4" axis="0 -1 0" range="-0.700924227600923 2.47766940613115" class="arm3_4"/>
              <geom mesh="right_arm_4" class="visual"/>
              <geom name="right_arm_4_1_collision" class="collision" type="sphere" size="0.033" pos="-0.01 0 0"  />
              <geom name="right_arm_4_2_collision" class="collision" type="cylinder" size="0.033 0.0535" pos="-0.01 0 -0.0565"  />

              <body name="right_arm_5" pos="-0.01 0 -0.122">
                <inertial pos="0.00000 0.01527 -0.13525" mass="0.43731" fullinertia="0.00222 0.00208 0.00044 0 0 0.00029"/>
                <joint name="joint_right_arm_5" axis="0 0 1" range="-3.14159265358979 3.14159265358979" class="arm5"/>
                <geom mesh="right_arm_5" class="visual"/>
                <geom name="right_arm_5_1_collision" class="collision" type="box" size="0.03 0.005 0.07" pos="0 0.04 -0.185"  />
                <geom name="right_arm_5_2_collision" class="collision" type="cylinder" size="0.033 0.104" pos="0 0 -0.104"  />
              </body>
            </body>
          </body>
        </body>
      </body>

      <body name="waist1" pos="0.030004 0 -0.3815">
        <inertial pos="-0.00588 -0.00001 0.02656" mass="2.58277" fullinertia="0.00144 0.00165 0.00202 0 -0.00033 0"/>
        <joint name="joint_waist1" axis="0 0 -1" range="-0.139626340159546 0.139626340159546" class="middle"/>
        <geom mesh="waist1" class="visual"/>

        <body name="waist2" pos="-0.06637 0 0">
          <inertial pos="-0.02324 0.00000 -0.01280" mass="7.47872" fullinertia="0.09227 0.00385 0.09080 0 0.00004 0"/>
          <joint name="joint_waist2" axis="1 0 0" range="-0.225322006432468 0.225322006432468" class="middle"/>
          <geom mesh="waist2" class="visual"/>
          <geom name="waist2_collision" class="collision" type="box" size="0.04 0.19 0.055" pos="-0.055 0 -0.025"  />

          <body name="left_leg_1" pos="0 0.135 -0.02">
            <inertial pos="0.06008 0.00001 -0.02669" mass="2.60468" fullinertia="0.00147 0.00171 0.00210 0 0.00027 0"/>
            <joint name="joint_left_leg_1" axis="-1 0 0" range="-1.570796326794897 0.332834288355319" class="middle"/>
            <geom mesh="left_leg_1" class="visual"/>
            <geom name="left_leg_1_collision" class="collision" type="cylinder" size="0.058 0.035" pos="0.065 0 -0.005"  />

            <body name="left_leg_2" pos="0.066366 0 -0.13989">
              <inertial pos="-0.00011 -0.01615 0.00843" mass="5.30032" fullinertia="0.01809 0.02679 0.01850 0 0.00001 -0.00076"/>
              <joint name="joint_left_leg_2" axis="0 0 1" range="-0.768643002578303 1.570796326794897" class="middle"/>
              <geom mesh="left_leg_2" class="visual"/>
              <geom name="left_leg_2_collision" class="collision" type="cylinder" size="0.075 0.0975" pos="0 0 0" euler="1.5708 0 0"  />

              <body name="left_leg_3" pos="0 0.029 0">
                <inertial pos="0.01384 -0.02509 -0.18332" mass="7.58273" fullinertia="0.08492 0.08577 0.01259 0.00049 0.00128 0.00266"/>
                <joint name="joint_left_leg_3" axis="0 -1 0" range="-1.641482161500667 1.290670981849807" class="leg3"/>
                <geom mesh="left_leg_3" class="visual"/>
                <geom name="left_leg_3_collision" class="collision" type="box" size="0.0675 0.065 0.1275" pos="0.025 -0.01 -0.210"  />

                <body name="left_leg_4" pos="0.034862 -0.001 -0.39848">
                  <inertial pos="-0.01394 -0.01517 -0.11510" mass="1.77554" fullinertia="0.02110 0.02143 0.00116 -0.00002 -0.00152 -0.00038"/>
                  <joint name="joint_left_leg_4" axis="0 1 0" range="-0.058817595792209 2.149896572606615" class="leg4"/>
                  <geom mesh="left_leg_4" class="visual"/>
                  <geom name="left_leg_4_collision" class="collision" type="box" size="0.0325 0.03 0.11" pos="0 0 -0.1"  />

                  <body name="left_wheel_1" pos="-0.031235 0.014 -0.3486">
                    <inertial pos="0.00000 -0.00472 0.00000" mass="1.59650" fullinertia="0.00580 0.01097 0.00580 0 0 0"/>
                    <joint name="joint_left_wheel_1" axis="0 1 0" class="wheel"/>
                    <geom mesh="left_wheel_1" class="visual"/>
                    <geom name="left_wheel_1_collision" class="collision" type="cylinder" size="0.107 0.0325" pos="0 -0.01 0" euler="1.5708 0 0"  />
                  </body>
                  <body name="left_leg_5" pos="-0.0087011 -0.0451 -0.097111">
                    <inertial pos="-0.00043 -0.02427 -0.17316" mass="0.57763" fullinertia="0.00454 0.00419 0.00054 0.00001 0 -0.00059"/>
                    <joint name="joint_left_leg_5" axis="0 1 0" range="-1.311963998724138 0" class="leg5"/>
                    <geom mesh="left_leg_5" class="visual"/>
                    <geom name="left_leg_5_collision" class="collision" type="box" size="0.025 0.0075 0.09" pos="0 -0.007 -0.08"  group="1"/>

                    <body name="left_wheel_2" pos="0 -0.043 -0.275">
                      <inertial pos="0.00000 0.00000 0.00000" mass="0.55913" fullinertia="0.00085 0.00144 0.00085 0 0 0"/>
                      <joint name="joint_left_wheel_2" type="hinge" axis="0 -1 0" damping="0" armature="0" frictionloss="0"/>
                      <geom mesh="left_wheel_2" class="visual"/>
                      <geom name="left_wheel_2_collision" class="collision" type="cylinder" size="0.075 0.0255" pos="0 0 0" euler="1.5708 0 0" friction="0.7 0.005 0.0001"/>
                    </body>
                  </body>
                </body>
              </body>
            </body>
          </body>

          <body name="right_leg_1" pos="0 -0.135 -0.02">
            <inertial pos="0.06008 0.00001 -0.02669" mass="2.60468" fullinertia="0.00147 0.00171 0.00210 0 0.00031 0"/>
            <joint name="joint_right_leg_1" axis="-1 0 0" range="-0.319918851890561 1.552819435499355" class="middle"/>
            <geom mesh="right_leg_1" class="visual"/>
            <geom name="right_leg_1_collision" class="collision" type="cylinder" size="0.058 0.035" pos="0.065 0 -0.005"  />

            <body name="right_leg_2" pos="0.066366 0 -0.13989">
              <inertial pos="0.00011 0.01615 0.00843" mass="5.30032" fullinertia="0.01809 0.02679 0.01850 0 -0.00001 0.00076"/>
              <joint name="joint_right_leg_2" axis="0 0 1" range="-1.570796326794897 0.768643002578303" class="middle"/>
              <geom mesh="right_leg_2" class="visual"/>
              <geom name="right_leg_2_collision" class="collision" type="cylinder" size="0.075 0.0975" pos="0 0 0" euler="1.5708 0 0"  />

              <body name="right_leg_3" pos="0 -0.03 0">
                <inertial pos="-0.01384 0.02509 -0.18332" mass="7.58273" fullinertia="0.08492 0.08577 0.01259 0.00049 -0.00128 -0.00266"/>
                <joint name="joint_right_leg_3" axis="0 1 0" range="-1.282293401440234 1.642005760276265" class="leg3"/>
                <geom mesh="right_leg_3" class="visual"/>
                <geom name="right_leg_3_collision" class="collision" type="box" size="0.0675 0.065 0.1275" pos="0.025 0.01 -0.210"  />

                <body name="right_leg_4" pos="0.034862 0.001 -0.39848">
                  <inertial pos="-0.01393 0.01521 -0.11509" mass="1.77554" fullinertia="0.02111 0.02143 0.00116 0.00002 -0.00152 0.00037"/>
                  <joint name="joint_right_leg_4" axis="0 -1 0" range="-2.147627644579023 0.058817595792209" class="leg4"/>
                  <geom mesh="right_leg_4" class="visual"/>
                  <geom name="right_leg_4_collision" class="collision" type="box" size="0.0325 0.03 0.11" pos="0 0 -0.1"  />

                  <body name="right_wheel_1" pos="-0.031235 -0.014 -0.3486">
                    <inertial pos="0.00000 0.00472 0.00000" mass="1.59650" fullinertia="0.00580 0.01097 0.00580 0 0 0"/>
                    <joint name="joint_right_wheel_1" axis="0 -1 0" class="wheel"/>
                    <geom mesh="right_wheel_1" class="visual"/>
                    <geom name="right_wheel_1_collision" class="collision" type="cylinder" size="0.107 0.0325" pos="0 0.01 0" euler="1.5708 0 0"  />
                  </body>
                  <body name="right_leg_5" pos="-0.0087011 0.0451 -0.097111">
                    <inertial pos="-0.00043 0.02425 -0.17316" mass="0.57763" fullinertia="0.00454 0.00419 0.00054 -0.00001 0 0.00059"/>
                    <joint name="joint_right_leg_5" axis="0 -1 0" range="0 1.311963998724138" class="leg5"/>
                    <geom mesh="right_leg_5" class="visual"/>
                    <geom name="right_leg_5_collision" class="collision" type="box" size="0.025 0.0075 0.09" pos="0 0.007 -0.08"  group="1"/>

                    <body name="right_wheel_2" pos="0 0.043 -0.275">
                      <inertial pos="0.00000 0.00000 0.00000" mass="0.55913" fullinertia="0.00085 0.00144 0.00085 0 0 0"/>
                      <joint name="joint_right_wheel_2" type="hinge" axis="0 1 0" damping="0" armature="0" frictionloss="0"/>
                      <geom mesh="right_wheel_2" class="visual"/>
                      <geom name="right_wheel_2_collision" class="collision" type="cylinder" size="0.075 0.0255" pos="0 0 0" euler="1.5708 0 0" friction="0.7 0.005 0.0001"/>
                    </body>
                  </body>
                </body>
              </body>
            </body>
          </body>
        </body>
      </body>
    </body>
  </worldbody>
  <!-- <actuator>
      <motor name="joint_left_arm_1" joint="joint_left_arm_1" ctrlrange="-107 107"/>
      <motor name="joint_right_arm_1" joint="joint_right_arm_1" ctrlrange="-107 107"/>
      <motor name="joint_left_arm_2" joint="joint_left_arm_2" ctrlrange="-107 107"/>
      <motor name="joint_right_arm_2" joint="joint_right_arm_2" ctrlrange="-107 107"/>
      <motor name="joint_left_arm_3" joint="joint_left_arm_3" ctrlrange="-49 49"/>
      <motor name="joint_right_arm_3" joint="joint_right_arm_3" ctrlrange="-49 49"/>
      <motor name="joint_left_arm_4" joint="joint_left_arm_4" ctrlrange="-49 49"/>
      <motor name="joint_right_arm_4" joint="joint_right_arm_4" ctrlrange="-49 49"/>
      <motor name="joint_left_arm_5" joint="joint_left_arm_5" ctrlrange="-13.5 13.5"/>
      <motor name="joint_right_arm_5" joint="joint_right_arm_5" ctrlrange="-13.5 13.5"/>
      <motor name="joint_waist1" joint="joint_waist1" ctrlrange="-133 133"/>
      <motor name="joint_waist2" joint="joint_waist2" ctrlrange="-133 133"/>
      <motor name="joint_left_leg_1" joint="joint_left_leg_1" ctrlrange="-133 133" />
      <motor name="joint_right_leg_1" joint="joint_right_leg_1" ctrlrange="-133 133" />
      <motor name="joint_left_leg_2" joint="joint_left_leg_2" ctrlrange="-133 133"/>
      <motor name="joint_right_leg_2" joint="joint_right_leg_2" ctrlrange="-133 133"/>
      <motor name="joint_left_leg_3" joint="joint_left_leg_3" ctrlrange="-267 267" />
      <motor name="joint_right_leg_3" joint="joint_right_leg_3" ctrlrange="-267 267" />
      <motor name="joint_left_leg_4" joint="joint_left_leg_4" ctrlrange="-267 267" />
      <motor name="joint_right_leg_4" joint="joint_right_leg_4" ctrlrange="-267 267" />
      <motor name="joint_left_leg_5" joint="joint_left_leg_5" ctrlrange="-1000 1000"/>
      <motor name="joint_right_leg_5" joint="joint_right_leg_5" ctrlrange="-1000 1000"/>
      <position name="joint_left_leg_5" joint="joint_left_leg_5" ctrlrange="-1.311963998724138 0" kp="2000" kv="100"/>
      <position name="joint_right_leg_5" joint="joint_right_leg_5" ctrlrange="0 1.311963998724138" kp="2000" kv="100"/>
      <motor name="joint_left_wheel_1" joint="joint_left_wheel_1" ctrlrange="-20 20"/>
      <motor name="joint_right_wheel_1" joint="joint_right_wheel_1" ctrlrange="-20 20"/>
      
  </actuator> -->
  <sensor>
    <framequat name="quat_sensor" objtype="site" objname="imu" />
    <gyro name="gyro_sensor" site="imu" />
    <accelerometer name="accel_sensor" site="imu" />
  </sensor>
  <!-- <equality>
    <weld name="head_to_mocap" body1="head" body2="head_mocap"/>
  </equality> -->
</mujoco>
